Workbook
Name Slicer_Category: #N/A
Name Slicer_Month: #N/A
Name Slicer_Region: #N/A

Sheet Data
A1: Transaction_ID | B1: Date | C1: Customer_ID | D1: Customer_Name | E1: Product_ID | F1: Product_Name | G1: Category | H1: Quantity | I1: Unit_Price | J1: Payment_Method | K1: Region | L1: Customer_Segment | M1: Customer_Since | N1: Total_Amount | O1: Month | P1: Year | Q1: Timestam | R1: Most Sold Product | S1: High Value Customers | T1: FILTER Function | AH1: Abbreviations
A2: TRX0155 | B2: 45393 | C2: CUST023 | D2: Paul Baker | E2: P009 | F2: Monitor | G2: Electronics | H2: 20.0008 | I2: 900 | J2: Cash | K2: Central | L2: Basic | M2: 44425 | N2: =H2*I2 -> 18000.72 | O2: =TEXT(Data!$B2,"mmm") -> Apr | P2: =YEAR(Data!$B2) -> 2024 | Q2: =NOW() -> 46122.659 | R2: {=INDEX(F2:F200,MODE(MATCH(F2:F200,F2:F200,0)))} -> Bookshelf | S2: =IF(N2>2000,"High Value","Normal") -> High Value | T2: {=_xlfn._xlws.FILTER(A2:N200, K2:K200="West")} -> TRX0092 | U2: 45403 | V2: CUST024 | W2: Dorothy Nelson | X2: P005 | Y2: Blender | Z2: Appliances | AA2: 2 | AB2: 59.99 | AC2: Cash | AD2: West | AE2: Standard | AF2: 44746 | AG2: 119.98 | AH2: =LEFT(D2,3) -> Pau
A3: TRX0023 | B3: 45396 | C3: CUST013 | D3: Joseph Jackson | E3: P009 | F3: Monitor | G3: Electronics | H3: 3 | I3: 249.99 | J3: Credit Card | K3: Central | L3: Premium | M3: 44575 | N3: =H3*I3 -> 749.97 | O3: =TEXT(Data!$B3,"mmm") -> Apr | P3: =YEAR(Data!$B3) -> 2024 | Q3: =NOW() -> 46122.659 | R3: {=INDEX(F3:F201,MODE(MATCH(F3:F201,F3:F201,0)))} -> Bookshelf | S3: =IF(N3>2000,"High Value","Normal") -> Normal | T3: TRX0185 | U3: 45408 | V3: CUST026 | W3: Karen Hill | X3: P005 | Y3: Blender | Z3: Appliances | AA3: 3 | AB3: 59.99 | AC3: Cash | AD3: West | AE3: Premium | AF3: 45207 | AG3: 179.97 | AH3: =LEFT(D3,3) -> Jos
A4: TRX0139 | B4: 45399 | C4: CUST021 | D4: Kevin Scott | E4: P005 | F4: Blender | G4: Appliances | H4: 3 | I4: 59.99 | J4: PayPal | K4: South | L4: Standard | M4: 45262 | N4: =H4*I4 -> 179.97 | O4: =TEXT(Data!$B4,"mmm") -> Apr | P4: =YEAR(Data!$B4) -> 2024 | Q4: =NOW() -> 46122.659 | R4: {=INDEX(F4:F202,MODE(MATCH(F4:F202,F4:F202,0)))} -> Bookshelf | S4: =IF(N4>2000,"High Value","Normal") -> Normal | T4: TRX0138 | U4: 45408 | V4: CUST022 | W4: Susan Green | X4: P008 | Y4: Bookshelf | Z4: Furniture | AA4: 1 | AB4: 149.99 | AC4: Credit Card | AD4: West | AE4: Standard | AF4: 45103 | AG4: 149.99 | AH4: =LEFT(D4,3) -> Kev
A5: TRX0043 | B5: 45400 | C5: CUST046 | D5: Kathleen Bennett | E5: P005 | F5: Blender | G5: Appliances | H5: 3 | I5: 59.99 | J5: Cash | K5: North | L5: Premium | M5: 45114 | N5: =H5*I5 -> 179.97 | O5: =TEXT(Data!$B5,"mmm") -> Apr | P5: =YEAR(Data!$B5) -> 2024 | Q5: =NOW() -> 46122.659 | R5: {=INDEX(F5:F203,MODE(MATCH(F5:F203,F5:F203,0)))} -> Bookshelf | S5: =IF(N5>2000,"High Value","Normal") -> Normal | T5: TRX0191 | U5: 45409 | V5: CUST038 | W5: Michelle Rogers | X5: P002 | Y5: Smartphone | Z5: Electronics | AA5: 3 | AB5: 699.99 | AC5: Credit Card | AD5: West | AE5: Basic | AF5: 44577 | AG5: 2099.97 | AH5: =LEFT(D5,3) -> Kat
A6: TRX0212 | B6: 45400 | C6: CUST003 | D6: Michael Brown | E6: P008 | F6: Bookshelf | G6: Furniture | H6: 5 | I6: 149.99 | J6: Credit Card | K6: North | L6: Premium | M6: 45295 | N6: =H6*I6 -> 749.95 | O6: =TEXT(Data!$B6,"mmm") -> Apr | P6: =YEAR(Data!$B6) -> 2024 | Q6: =NOW() -> 46122.659 | R6: {=INDEX(F6:F204,MODE(MATCH(F6:F204,F6:F204,0)))} -> Bookshelf | S6: =IF(N6>2000,"High Value","Normal") -> Normal | T6: TRX0122 | U6: 45410 | V6: CUST025 | W6: Mark Carter | X6: P001 | Y6: Laptop | Z6: Electronics | AA6: 4 | AB6: 899.99 | AC6: Credit Card | AD6: West | AE6: Standard | AF6: 45327 | AG6: 3599.96 | AH6: =LEFT(D6,3) -> Mic
A7: TRX0092 | B7: 45403 | C7: CUST024 | D7: Dorothy Nelson | E7: P005 | F7: Blender | G7: Appliances | H7: 2 | I7: 59.99 | J7: Cash | K7: West | L7: Standard | M7: 44746 | N7: =H7*I7 -> 119.98 | O7: =TEXT(Data!$B7,"mmm") -> Apr | P7: =YEAR(Data!$B7) -> 2024 | Q7: =NOW() -> 46122.659 | R7: {=INDEX(F7:F205,MODE(MATCH(F7:F205,F7:F205,0)))} -> Keyboard | S7: =IF(N7>2000,"High Value","Normal") -> Normal | T7: TRX0231 | U7: 45412 | V7: CUST018 | W7: Barbara Young | X7: P002 | Y7: Smartphone | Z7: Electronics | AA7: 5 | AB7: 699.99 | AC7: Cash | AD7: West | AE7: Basic | AF7: 45167 | AG7: 3499.95 | AH7: =LEFT(D7,3) -> Dor
A8: TRX0193 | B8: 45403 | C8: CUST024 | D8: Dorothy Nelson | E8: P003 | F8: Headphones | G8: Electronics | H8: 5 | I8: 149.99 | J8: Credit Card | K8: Central | L8: Standard | M8: 44418 | N8: =H8*I8 -> 749.95 | O8: =TEXT(Data!$B8,"mmm") -> Apr | P8: =YEAR(Data!$B8) -> 2024 | Q8: =NOW() -> 46122.659 | R8: {=INDEX(F8:F206,MODE(MATCH(F8:F206,F8:F206,0)))} -> Keyboard | S8: =IF(N8>2000,"High Value","Normal") -> Normal | T8: TRX0242 | U8: 45416 | V8: CUST025 | W8: Mark Carter | X8: P007 | Y8: Desk | Z8: Furniture | AA8: 4 | AB8: 299.99 | AC8: Cash | AD8: West | AE8: Premium | AF8: 44716 | AG8: 1199.96 | AH8: =LEFT(D8,3) -> Dor
A9: TRX0240 | B9: 45403 | C9: CUST017 | D9: Charles Allen | E9: P005 | F9: Blender | G9: Appliances | H9: 3 | I9: 100 | J9: Debit Card | K9: South | L9: Basic | M9: 45007 | N9: =H9*I9 -> 300 | O9: =TEXT(Data!$B9,"mmm") -> Apr | P9: =YEAR(Data!$B9) -> 2024 | Q9: =NOW() -> 46122.659 | R9: {=INDEX(F9:F207,MODE(MATCH(F9:F207,F9:F207,0)))} -> Keyboard | S9: =IF(N9>2000,"High Value","Normal") -> Normal | T9: TRX0071 | U9: 45422 | V9: CUST036 | W9: Nancy Collins | X9: P009 | Y9: Monitor | Z9: Electronics | AA9: 5 | AB9: 249.99 | AC9: Credit Card | AD9: West | AE9: Standard | AF9: 44525 | AG9: 1249.95 | AH9: =LEFT(D9,3) -> Cha
A10: TRX0135 | B10: 45405 | C10: CUST009 | D10: Robert Thomas | E10: P001 | F10: Laptop | G10: Electronics | H10: 3 | I10: 899.99 | J10: PayPal | K10: East | L10: Standard | M10: 45299 | N10: =H10*I10 -> 2699.97 | O10: =TEXT(Data!$B10,"mmm") -> Apr | P10: =YEAR(Data!$B10) -> 2024 | Q10: =NOW() -> 46122.659 | R10: {=INDEX(F10:F208,MODE(MATCH(F10:F208,F10:F208,0)))} -> Keyboard | S10: =IF(N10>2000,"High Value","Normal") -> High Value | T10: TRX0194 | U10: 45428 | V10: CUST006 | W10: Lisa Anderson | X10: P008 | Y10: Bookshelf | Z10: Furniture | AA10: 2 | AB10: 149.99 | AC10: Credit Card | AD10: West | AE10: Basic | AF10: 44823 | AG10: 299.98 | AH10: =LEFT(D10,3) -> Rob
A11: TRX0185 | B11: 45408 | C11: CUST026 | D11: Karen Hill | E11: P005 | F11: Blender | G11: Appliances | H11: 3 | I11: 59.99 | J11: Cash | K11: West | L11: Premium | M11: 45207 | N11: =H11*I11 -> 179.97 | O11: =TEXT(Data!$B11,"mmm") -> Apr | P11: =YEAR(Data!$B11) -> 2024 | Q11: =NOW() -> 46122.659 | R11: {=INDEX(F11:F209,MODE(MATCH(F11:F209,F11:F209,0)))} -> Keyboard | S11: =IF(N11>2000,"High Value","Normal") -> Normal | T11: TRX0130 | U11: 45430 | V11: CUST002 | W11: Emma Wilson | X11: P008 | Y11: Bookshelf | Z11: Furniture | AA11: 3 | AB11: 149.99 | AC11: Credit Card | AD11: West | AE11: Premium | AF11: 45068 | AG11: 449.97 | AH11: =LEFT(D11,3) -> Kar
A12: TRX0138 | B12: 45408 | C12: CUST022 | D12: Susan Green | E12: P008 | F12: Bookshelf | G12: Furniture | H12: 1 | I12: 149.99 | J12: Credit Card | K12: West | L12: Standard | M12: 45103 | N12: =H12*I12 -> 149.99 | O12: =TEXT(Data!$B12,"mmm") -> Apr | P12: =YEAR(Data!$B12) -> 2024 | Q12: =NOW() -> 46122.659 | R12: {=INDEX(F12:F210,MODE(MATCH(F12:F210,F12:F210,0)))} -> Keyboard | S12: =IF(N12>2000,"High Value","Normal") -> Normal | T12: TRX0041 | U12: 45432 | V12: CUST021 | W12: Kevin Scott | X12: P001 | Y12: Laptop | Z12: Electronics | AA12: 1 | AB12: 899.99 | AC12: Credit Card | AD12: West | AE12: Premium | AF12: 44578 | AG12: 899.99 | AH12: =LEFT(D12,3) -> Sus
A13: TRX0209 | B13: 45408 | C13: CUST046 | D13: Kathleen Bennett | E13: P008 | F13: Bookshelf | G13: Furniture | H13: 5 | I13: 149.99 | J13: Debit Card | K13: North | L13: Basic | M13: 44830 | N13: =H13*I13 -> 749.95 | O13: =TEXT(Data!$B13,"mmm") -> Apr | P13: =YEAR(Data!$B13) -> 2024 | Q13: =NOW() -> 46122.659 | R13: {=INDEX(F13:F211,MODE(MATCH(F13:F211,F13:F211,0)))} -> Keyboard | S13: =IF(N13>2000,"High Value","Normal") -> Normal | T13: TRX0015 | U13: 45440 | V13: CUST008 | W13: Jennifer Taylor | X13: P002 | Y13: Smartphone | Z13: Electronics | AA13: 5 | AB13: 699.99 | AC13: PayPal | AD13: West | AE13: Standard | AF13: 44407 | AG13: 3499.95 | AH13: =LEFT(D13,3) -> Kat
A14: TRX0246 | B14: 45408 | C14: CUST041 | D14: Peter Richardson | E14: P008 | F14: Bookshelf | G14: Furniture | H14: 3 | I14: 149.99 | J14: Cash | K14: North | L14: Premium | M14: 44806 | N14: =H14*I14 -> 449.97 | O14: =TEXT(Data!$B14,"mmm") -> Apr | P14: =YEAR(Data!$B14) -> 2024 | Q14: =NOW() -> 46122.659 | R14: {=INDEX(F14:F212,MODE(MATCH(F14:F212,F14:F212,0)))} -> Keyboard | S14: =IF(N14>2000,"High Value","Normal") -> Normal | T14: TRX0128 | U14: 45444 | V14: CUST040 | W14: Sharon Butler | X14: P005 | Y14: Blender | Z14: Appliances | AA14: 2 | AB14: 59.99 | AC14: Cash | AD14: West | AE14: Basic | AF14: 45390 | AG14: 119.98 | AH14: =LEFT(D14,3) -> Pet
... A34: TRX0130 | B34: 45430 | C34: CUST002 | D34: Emma Wilson | E34: P008 | F34: Bookshelf | G34: Furniture | H34: 3 | I34: 149.99 | J34: Credit Card | K34: West | L34: Premium | M34: 45068 | N34: =H34*I34 -> 449.97 | O34: =TEXT(Data!$B34,"mmm") -> May | P34: =YEAR(Data!$B34) -> 2024 | Q34: =NOW() -> 46122.659 | R34: {=INDEX(F34:F232,MODE(MATCH(F34:F232,F34:F232,0)))} -> Keyboard | S34: =IF(N34>2000,"High Value","Normal") -> Normal | T34: TRX0143 | U34: 45654 | V34: CUST003 | W34: Michael Brown | X34: P007 | Y34: Desk | Z34: Furniture | AA34: 2 | AB34: 299.99 | AC34: Cash | AD34: West | AE34: Basic | AF34: 44771 | AG34: 599.98 | AH34: =LEFT(D34,3) -> Emm
A35: TRX0041 | B35: 45432 | C35: CUST021 | D35: Kevin Scott | E35: P001 | F35: Laptop | G35: Electronics | H35: 1 | I35: 899.99 | J35: Credit Card | K35: West | L35: Premium | M35: 44578 | N35: =H35*I35 -> 899.99 | O35: =TEXT(Data!$B35,"mmm") -> May | P35: =YEAR(Data!$B35) -> 2024 | Q35: =NOW() -> 46122.659 | R35: {=INDEX(F35:F233,MODE(MATCH(F35:F233,F35:F233,0)))} -> Keyboard | S35: =IF(N35>2000,"High Value","Normal") -> Normal | AH35: =LEFT(D35,3) -> Kev
A36: TRX0232 | B36: 45434 | C36: CUST012 | D36: Patricia Moore | E36: P007 | F36: Desk | G36: Furniture | H36: 3 | I36: 299.99 | J36: Credit Card | K36: East | L36: Basic | M36: 44824 | N36: =H36*I36 -> 899.97 | O36: =TEXT(Data!$B36,"mmm") -> May | P36: =YEAR(Data!$B36) -> 2024 | Q36: =NOW() -> 46122.659 | R36: {=INDEX(F36:F234,MODE(MATCH(F36:F234,F36:F234,0)))} -> Keyboard | S36: =IF(N36>2000,"High Value","Normal") -> Normal | AH36: =LEFT(D36,3) -> Pat
A37: TRX0021 | B37: 45435 | C37: CUST006 | D37: Lisa Anderson | E37: P004 | F37: Coffee Maker | G37: Appliances | H37: 3 | I37: 79.99 | J37: Cash | K37: South | L37: Basic | M37: 45046 | N37: =H37*I37 -> 239.97 | O37: =TEXT(Data!$B37,"mmm") -> May | P37: =YEAR(Data!$B37) -> 2024 | Q37: =NOW() -> 46122.659 | R37: {=INDEX(F37:F235,MODE(MATCH(F37:F235,F37:F235,0)))} -> Keyboard | S37: =IF(N37>2000,"High Value","Normal") -> Normal | AH37: =LEFT(D37,3) -> Lis
A38: TRX0245 | B38: 45438 | C38: CUST031 | D38: Steven Turner | E38: P006 | F38: Office Chair | G38: Furniture | H38: 3 | I38: 199.99 | J38: Credit Card | K38: North | L38: Premium | M38: 45292 | N38: =H38*I38 -> 599.97 | O38: =TEXT(Data!$B38,"mmm") -> May | P38: =YEAR(Data!$B38) -> 2024 | Q38: =NOW() -> 46122.659 | R38: {=INDEX(F38:F236,MODE(MATCH(F38:F236,F38:F236,0)))} -> Keyboard | S38: =IF(N38>2000,"High Value","Normal") -> Normal | AH38: =LEFT(D38,3) -> Ste
A39: TRX0015 | B39: 45440 | C39: CUST008 | D39: Jennifer Taylor | E39: P002 | F39: Smartphone | G39: Electronics | H39: 5 | I39: 699.99 | J39: PayPal | K39: West | L39: Standard | M39: 44407 | N39: =H39*I39 -> 3499.95 | O39: =TEXT(Data!$B39,"mmm") -> May | P39: =YEAR(Data!$B39) -> 2024 | Q39: =NOW() -> 46122.659 | R39: {=INDEX(F39:F237,MODE(MATCH(F39:F237,F39:F237,0)))} -> Keyboard | S39: =IF(N39>2000,"High Value","Normal") -> High Value | AH39: =LEFT(D39,3) -> Jen
A40: TRX0202 | B40: 45441 | C40: CUST035 | D40: Harry Morgan | E40: P010 | F40: Keyboard | G40: Electronics | H40: 3 | I40: 89.99 | J40: PayPal | K40: Central | L40: Premium | M40: 45120 | N40: =H40*I40 -> 269.97 | O40: =TEXT(Data!$B40,"mmm") -> May | P40: =YEAR(Data!$B40) -> 2024 | Q40: =NOW() -> 46122.659 | R40: {=INDEX(F40:F238,MODE(MATCH(F40:F238,F40:F238,0)))} -> Keyboard | S40: =IF(N40>2000,"High Value","Normal") -> Normal | AH40: =LEFT(D40,3) -> Har
A41: TRX0042 | B41: 45443 | C41: CUST019 | D41: Daniel King | E41: P004 | F41: Coffee Maker | G41: Appliances | H41: 1 | I41: 79.99 | J41: Cash | K41: North | L41: Standard | M41: 44917 | N41: =H41*I41 -> 79.99 | O41: =TEXT(Data!$B41,"mmm") -> May | P41: =YEAR(Data!$B41) -> 2024 | Q41: =NOW() -> 46122.659 | R41: {=INDEX(F41:F239,MODE(MATCH(F41:F239,F41:F239,0)))} -> Keyboard | S41: =IF(N41>2000,"High Value","Normal") -> Normal | AH41: =LEFT(D41,3) -> Dan
A42: TRX0128 | B42: 45444 | C42: CUST040 | D42: Sharon Butler | E42: P005 | F42: Blender | G42: Appliances | H42: 2 | I42: 59.99 | J42: Cash | K42: West | L42: Basic | M42: 45390 | N42: =H42*I42 -> 119.98 | O42: =TEXT(Data!$B42,"mmm") -> Jun | P42: =YEAR(Data!$B42) -> 2024 | Q42: =NOW() -> 46122.659 | R42: {=INDEX(F42:F240,MODE(MATCH(F42:F240,F42:F240,0)))} -> Keyboard | S42: =IF(N42>2000,"High Value","Normal") -> Normal | AH42: =LEFT(D42,3) -> Sha
A43: TRX0117 | B43: 45444 | C43: CUST017 | D43: Charles Allen | E43: P010 | F43: Keyboard | G43: Electronics | H43: 1 | I43: 89.99 | J43: Cash | K43: North | L43: Basic | M43: 45141 | N43: =H43*I43 -> 89.99 | O43: =TEXT(Data!$B43,"mmm") -> Jun | P43: =YEAR(Data!$B43) -> 2024 | Q43: =NOW() -> 46122.659 | R43: {=INDEX(F43:F241,MODE(MATCH(F43:F241,F43:F241,0)))} -> Keyboard | S43: =IF(N43>2000,"High Value","Normal") -> Normal | AH43: =LEFT(D43,3) -> Cha
A44: TRX0208 | B44: 45446 | C44: CUST004 | D44: Sarah Davis | E44: P010 | F44: Keyboard | G44: Electronics | H44: 5 | I44: 89.99 | J44: Credit Card | K44: East | L44: Standard | M44: 44587 | N44: =H44*I44 -> 449.95 | O44: =TEXT(Data!$B44,"mmm") -> Jun | P44: =YEAR(Data!$B44) -> 2024 | Q44: =NOW() -> 46122.659 | R44: {=INDEX(F44:F242,MODE(MATCH(F44:F242,F44:F242,0)))} -> Keyboard | S44: =IF(N44>2000,"High Value","Normal") -> Normal | AH44: =LEFT(D44,3) -> Sar
A45: TRX0234 | B45: 45449 | C45: CUST013 | D45: Joseph Jackson | E45: P009 | F45: Monitor | G45: Electronics | H45: 5 | I45: 249.99 | J45: Credit Card | K45: East | L45: Standard | M45: 44707 | N45: =H45*I45 -> 1249.95 | O45: =TEXT(Data!$B45,"mmm") -> Jun | P45: =YEAR(Data!$B45) -> 2024 | Q45: =NOW() -> 46122.659 | R45: {=INDEX(F45:F243,MODE(MATCH(F45:F243,F45:F243,0)))} -> Bookshelf | S45: =IF(N45>2000,"High Value","Normal") -> Normal | AH45: =LEFT(D45,3) -> Jos
A46: TRX0121 | B46: 45449 | C46: CUST028 | D46: Betty Campbell | E46: P010 | F46: Keyboard | G46: Electronics | H46: 1 | I46: 89.99 | J46: Credit Card | K46: South | L46: Standard | M46: 44582 | N46: =H46*I46 -> 89.99 | O46: =TEXT(Data!$B46,"mmm") -> Jun | P46: =YEAR(Data!$B46) -> 2024 | Q46: =NOW() -> 46122.659 | R46: {=INDEX(F46:F244,MODE(MATCH(F46:F244,F46:F244,0)))} -> Bookshelf | S46: =IF(N46>2000,"High Value","Normal") -> Normal | AH46: =LEFT(D46,3) -> Bet
... A53: TRX0061 | B53: 45460 | C53: CUST028 | D53: Betty Campbell | E53: P005 | F53: Blender | G53: Appliances | H53: 1 | I53: 59.99 | J53: Debit Card | K53: West | L53: Premium | M53: 45190 | N53: =H53*I53 -> 59.99 | O53: =TEXT(Data!$B53,"mmm") -> Jun | P53: =YEAR(Data!$B53) -> 2024 | Q53: =NOW() -> 46122.659 | R53: {=INDEX(F53:F251,MODE(MATCH(F53:F251,F53:F251,0)))} -> Keyboard | S53: =IF(N53>2000,"High Value","Normal") -> Normal | AH53: =LEFT(D53,3) -> Bet
A54: TRX0150 | B54: 45460 | C54: CUST008 | D54: Jennifer Taylor | E54: P007 | F54: Desk | G54: Furniture | H54: 2 | I54: 299.99 | J54: Debit Card | K54: East | L54: Standard | M54: 45253 | N54: =H54*I54 -> 599.98 | O54: =TEXT(Data!$B54,"mmm") -> Jun | P54: =YEAR(Data!$B54) -> 2024 | Q54: =NOW() -> 46122.659 | S54: =IF(N54>2000,"High Value","Normal") -> Normal | AH54: =LEFT(D54,3) -> Jen
A55: TRX0025 | B55: 45468 | C55: CUST049 | D55: Raymond Ross | E55: P010 | F55: Keyboard | G55: Electronics | H55: 4 | I55: 89.99 | J55: Debit Card | K55: South | L55: Basic | M55: 45281 | N55: =H55*I55 -> 359.96 | O55: =TEXT(Data!$B55,"mmm") -> Jun | P55: =YEAR(Data!$B55) -> 2024 | Q55: =NOW() -> 46122.659 | S55: =IF(N55>2000,"High Value","Normal") -> Normal | AH55: =LEFT(D55,3) -> Ray
A56: TRX0078 | B56: 45469 | C56: CUST021 | D56: Kevin Scott | E56: P004 | F56: Coffee Maker | G56: Appliances | H56: 1 | I56: 79.99 | J56: PayPal | K56: Central | L56: Premium | M56: 45352 | N56: =H56*I56 -> 79.99 | O56: =TEXT(Data!$B56,"mmm") -> Jun | P56: =YEAR(Data!$B56) -> 2024 | Q56: =NOW() -> 46122.659 | S56: =IF(N56>2000,"High Value","Normal") -> Normal | AH56: =LEFT(D56,3) -> Kev
A57: TRX0007 | B57: 45469 | C57: CUST009 | D57: Robert Thomas | E57: P010 | F57: Keyboard | G57: Electronics | H57: 2 | I57: 89.99 | J57: Cash | K57: West | L57: Basic | M57: 44438 | N57: =H57*I57 -> 179.98 | O57: =TEXT(Data!$B57,"mmm") -> Jun | P57: =YEAR(Data!$B57) -> 2024 | Q57: =NOW() -> 46122.659 | S57: =IF(N57>2000,"High Value","Normal") -> Normal | AH57: =LEFT(D57,3) -> Rob
A58: TRX0184 | B58: 45471 | C58: CUST046 | D58: Kathleen Bennett | E58: P002 | F58: Smartphone | G58: Electronics | H58: 3 | I58: 699.99 | J58: Credit Card | K58: East | L58: Premium | M58: 45102 | N58: =H58*I58 -> 2099.97 | O58: =TEXT(Data!$B58,"mmm") -> Jun | P58: =YEAR(Data!$B58) -> 2024 | Q58: =NOW() -> 46122.659 | S58: =IF(N58>2000,"High Value","Normal") -> High Value | AH58: =LEFT(D58,3) -> Kat
A59: TRX0104 | B59: 45471 | C59: CUST012 | D59: Patricia Moore | E59: P001 | F59: Laptop | G59: Electronics | H59: 4 | I59: 899.99 | J59: Credit Card | K59: East | L59: Premium | M59: 44993 | N59: =H59*I59 -> 3599.96 | O59: =TEXT(Data!$B59,"mmm") -> Jun | P59: =YEAR(Data!$B59) -> 2024 | Q59: =NOW() -> 46122.659 | S59: =IF(N59>2000,"High Value","Normal") -> High Value | AH59: =LEFT(D59,3) -> Pat
A60: TRX0127 | B60: 45472 | C60: CUST030 | D60: Helen Roberts | E60: P008 | F60: Bookshelf | G60: Furniture | H60: 1 | I60: 149.99 | J60: PayPal | K60: East | L60: Basic | M60: 44851 | N60: =H60*I60 -> 149.99 | O60: =TEXT(Data!$B60,"mmm") -> Jun | P60: =YEAR(Data!$B60) -> 2024 | Q60: =NOW() -> 46122.659 | S60: =IF(N60>2000,"High Value","Normal") -> Normal | AH60: =LEFT(D60,3) -> Hel
A61: TRX0096 | B61: 45474 | C61: CUST002 | D61: Emma Wilson | E61: P010 | F61: Keyboard | G61: Electronics | H61: 2 | I61: 89.99 | J61: PayPal | K61: Central | L61: Premium | M61: 45275 | N61: =H61*I61 -> 179.98 | O61: =TEXT(Data!$B61,"mmm") -> Jul | P61: =YEAR(Data!$B61) -> 2024 | Q61: =NOW() -> 46122.659 | S61: =IF(N61>2000,"High Value","Normal") -> Normal | AH61: =LEFT(D61,3) -> Emm
A62: TRX0192 | B62: 45475 | C62: CUST017 | D62: Charles Allen | E62: P010 | F62: Keyboard | G62: Electronics | H62: 1 | I62: 89.99 | J62: PayPal | K62: West | L62: Standard | M62: 44802 | N62: =H62*I62 -> 89.99 | O62: =TEXT(Data!$B62,"mmm") -> Jul | P62: =YEAR(Data!$B62) -> 2024 | Q62: =NOW() -> 46122.659 | S62: =IF(N62>2000,"High Value","Normal") -> Normal | AH62: =LEFT(D62,3) -> Cha
A63: TRX0052 | B63: 45476 | C63: CUST022 | D63: Susan Green | E63: P010 | F63: Keyboard | G63: Electronics | H63: 1 | I63: 89.99 | J63: Cash | K63: South | L63: Standard | M63: 44611 | N63: =H63*I63 -> 89.99 | O63: =TEXT(Data!$B63,"mmm") -> Jul | P63: =YEAR(Data!$B63) -> 2024 | Q63: =NOW() -> 46122.659 | S63: =IF(N63>2000,"High Value","Normal") -> Normal | AH63: =LEFT(D63,3) -> Sus
A64: TRX0070 | B64: 45476 | C64: CUST007 | D64: David Martinez | E64: P004 | F64: Coffee Maker | G64: Appliances | H64: 5 | I64: 79.99 | J64: Debit Card | K64: Central | L64: Basic | M64: 44981 | N64: =H64*I64 -> 399.95 | O64: =TEXT(Data!$B64,"mmm") -> Jul | P64: =YEAR(Data!$B64) -> 2024 | Q64: =NOW() -> 46122.659 | S64: =IF(N64>2000,"High Value","Normal") -> Normal | AH64: =LEFT(D64,3) -> Dav
A65: TRX0086 | B65: 45481 | C65: CUST020 | D65: Margaret Wright | E65: P008 | F65: Bookshelf | G65: Furniture | H65: 1 | I65: 149.99 | J65: PayPal | K65: North | L65: Basic | M65: 44421 | N65: =H65*I65 -> 149.99 | O65: =TEXT(Data!$B65,"mmm") -> Jul | P65: =YEAR(Data!$B65) -> 2024 | Q65: =NOW() -> 46122.659 | S65: =IF(N65>2000,"High Value","Normal") -> Normal | AH65: =LEFT(D65,3) -> Mar
...

Sheet  Regression
A1: SUMMARY OUTPUT
A3: Regression Statistics
A4: Multiple R | B4: 0.69971717
A5: R Square | B5: 0.48960411
A6: Adjusted R Square | B6: 0.48754607
A7: Standard Error | B7: 1069.6
A8: Observations | B8: 250
A10: ANOVA
B11: df | C11: SS | D11: MS | E11: F | F11: Significance F
A12: Regression | B12: 1 | C12: 2.7216504e+08 | D12: 2.7216504e+08 | E12: 237.89733 | F12: 4.3456001e-38
A13: Residual | B13: 248 | C13: 2.8372294e+08 | D13: 1144044.1
A14: Total | B14: 249 | C14: 5.5588798e+08
B16: Coefficients | C16: Standard Error | D16: t Stat | E16: P-value | F16: Lower 95% | G16: Upper 95% | H16: Lower 95.0% | I16: Upper 95.0%
A17: Intercept | B17: -891.26947 | C17: 139.26189 | D17: -6.3999525 | E17: 7.7056687e-10 | F17: -1165.5563 | G17: -616.98264 | H17: -1165.5563 | I17: -616.98264
A18: X Variable 1 | B18: 609.58458 | C18: 39.522025 | D18: 15.423921 | E18: 4.3456001e-38 | F18: 531.74297 | G18: 687.4262 | H18: 531.74297 | I18: 687.4262

Sheet Pivot Tables
A1: Sales by Region
A3: Row Labels | B3: Sum of Total_Amount
A4: Central | B4: 41288.34
A5: East | B5: 59288.39
A6: North | B6: 50808.31
A7: South | B7: 36398.75
A8: West | B8: 41408.68
A9: Grand Total | B9: 229192.47
A11: Sales by Category
A13: Row Labels | B13: Sum of Total_Amount
A14: Appliances | B14: 8338.74
A15: Electronics | B15: 171756.05
A16: Furniture | B16: 49097.68
A17: Grand Total | B17: 229192.47
A19: Monthly Sales Trend
A21: Row Labels | B21: Sum of Total_Amount
A22: Jan | B22: 25799.15
A23: Feb | B23: 16069.38
A24: Mar | B24: 19899.38
A25: Apr | B25: 27899.16
A26: May | B26: 17039.35
A27: Jun | B27: 19299.45
A28: Jul | B28: 18479.4
A29: Aug | B29: 15759.43
A30: Sep | B30: 12989.51
A31: Oct | B31: 20609.52
A32: Nov | B32: 12309.44
A33: Dec | B33: 23039.3
A34: Grand Total | B34: 229192.47

Sheet Dashbord
I1: Customer Sales Analysis Dashboard
C5: Total Sales | H5: Total Orders | M5: Total Customers | R5: Best Region
C6: =SUM(Data!N2:N253) -> 246563.25 | H6: =COUNTA(Data!$A$2:$A$251) -> 250 | M6: =COUNTA(_xlfn.UNIQUE(Data!$C$2:$C$251)) -> 50 | R6: =INDEX(Data!$K$2:$K$251,MATCH(MAX(Data!$N$2:$N$251),Data!$N$2:$N$251,0)) -> Central

Sheet Documentation
A1: 1. Dataset Information
A3: Total Records: 200+
A4: Columns: Transaction_ID, Date, Customer_ID, Product, etc.
A5: Time Period: 2024–2025
A7: 2. Steps
A9: Data cleaning (TRIM, remove errors)
A10: Table create kiya
A11: Formulas apply kiye
A12: Pivot Tables banaye
A13: Charts create kiye
A14: Dashboard design kiya
A16: 3. Dashboard
... A25: Top Region

Sheet Insights
A1: Sales Insights
A3: Electronics category has highest sales
A4: Smartphones and Laptops are top-selling product
A6: Region Insights
A8: West/North region generates highest revenue
A9: Some regions have low performance
A11: Payment Insights
A13: Credit Card / Cash most used method
